# Demonstrate the use of multiple catch blocks to handle different types of exceptions in a single try block. [Medium]

```java

public class MultipleCatchDemo {
    public static void main(String[] args) {
        try {
          
            int a = 10 / 0;

            // Case 2: ArrayIndexOutOfBoundsException
            int[] arr = new int[3];
            System.out.println(arr[5]);

            String str = "abc";
            int num = Integer.parseInt(str);

        } catch (ArithmeticException e) {
            System.out.println("Caught ArithmeticException: " + e.getMessage());
        } catch (ArrayIndexOutOfBoundsException e) {
            System.out.println("Caught ArrayIndexOutOfBoundsException: " + e.getMessage());
        } catch (NumberFormatException e) {
            System.out.println("Caught NumberFormatException: " + e.getMessage());
        } catch (Exception e) { 
            
            System.out.println("Caught Exception: " + e.getMessage());
        }

        System.out.println("Program continues after handling exceptions...");
    }
}


```

## Output:

```java

Caught ArithmeticException: / by zero
Program continues after handling exceptions...

```
